<?xml version="1.0" ?>
<robot name="steering" xmlns:xacro="http://ros.org/wiki/xacro">

  <!-- wheel_link -->
  <xacro:include filename="$(find adrv_description)/urdf/wheel.urdf.xacro" />

  <!-- front_steer_shaft_link -->
  <xacro:macro name="front_steer_shaft" params="base pose_xyz">

    <link name="front_steer_shaft_link" >
      <inertial>
        <mass value="1.0" />
        <inertia ixx="1.0" ixy="0.0" ixz="0.0"
          iyy="1.0" iyz="0.0"
          izz="1.0" />
      </inertial>
    </link>

    <joint name="front_steer_shaft_joint" type="fixed">
      <parent link="${base}" />
      <child link="front_steer_shaft_link" />      
      <origin xyz="${pose_xyz}" rpy="0 0 0" />
      <axis xyz="0 1 0" />
    </joint>

  </xacro:macro>

  <!-- rear_wheel_shaft -->
  <xacro:macro name="rear_wheel_shaft" params="base pose_xyz tread radius">

    <link name="rear_wheel_shaft_link" />    

    <joint name="rear_wheel_shaft_joint" type="continuous">
      <parent link="${base}" />
      <child link="rear_wheel_shaft_link" />      
      <origin xyz="${pose_xyz}" rpy="0 0 0" />
      <axis xyz="0 1 0" />
    </joint>

  </xacro:macro>

  <!-- rear_wheel_link -->
  <xacro:macro name="rear_wheel" params="name base pose_xyz right_left">    

    <xacro:wheel name="${name}" right_left="${right_left}" />

    <joint name="${name}_joint" type="continuous">
      <parent link="${base}" />
      <child link="${name}_link" />
      <origin xyz="${pose_xyz}" rpy="0 0 0" />
      <axis xyz="0 1 0" />
    </joint>      

    <transmission name="${name}_trans" type="SimpleTransmission">
      <type>transmission_interface/SimpleTransmission</type>
      <joint name="${name}_joint">
        <hardwareInterface>hardware_interface/VelocityJointInterface</hardwareInterface>
      </joint>
      <actuator name="${name}_motor">
        <hardwareInterface>hardware_interface/VelocityJointInterface</hardwareInterface>
        <mechanicalReduction>1</mechanicalReduction>        
      </actuator>
    </transmission>

  </xacro:macro>

  <!-- front_wheel_link -->
  <xacro:macro name="front_wheel" params="name base pose_xyz right_left">
    
    <link name="${name}_steer_link" >
      <inertial>
        <mass value="1.0" />
        <inertia ixx="1.0" ixy="0.0" ixz="0.0"
          iyy="1.0" iyz="0.0"
          izz="1.0" />
      </inertial>
    </link>

    <joint name="${name}_steer_joint" type="revolute">          
      <parent link="${base}" />
      <child link="${name}_steer_link" />
      <origin xyz="${pose_xyz}" rpy="0 0 0" />
      <axis xyz="0 0 -1" /> 
      <limit lower="${-M_PI/3}" upper="${M_PI/3}" effort="7.0" velocity="2.16"/>
      <dynamics damping="0.0" friction="0.0"/>
    </joint>

    <xacro:wheel name="${name}" right_left="${right_left}" />

    <joint name="${name}_joint" type="continuous">
      <parent link="${name}_steer_link" />      
      <child link="${name}_link" />
      <origin xyz="0 0 0" rpy="0 0 0" />      
      <axis xyz="0 1 0" />
    </joint>

    <transmission name="${name}_steer_trans" type="SimpleTransmission">
      <type>transmission_interface/SimpleTransmission</type>
      <joint name="${name}_steer_joint">
        <hardwareInterface>hardware_interface/PositionJointInterface</hardwareInterface>
      </joint>
      <actuator name="${right_left}_steer_motor">
        <hardwareInterface>hardware_interface/PositionJointInterface</hardwareInterface>
        <mechanicalReduction>1</mechanicalReduction>
      </actuator>
    </transmission>

    <transmission name="${name}_trans" type="SimpleTransmission">
      <type>transmission_interface/SimpleTransmission</type>
      <joint name="${name}_joint">
        <hardwareInterface>hardware_interface/VelocityJointInterface</hardwareInterface>
      </joint>
      <actuator name="${right_left}_motor">
        <hardwareInterface>hardware_interface/VelocityJointInterface</hardwareInterface>
        <mechanicalReduction>1</mechanicalReduction>
      </actuator>
    </transmission>

  </xacro:macro>
  
</robot>
